Workbook

Sheet VOXX
A1: latest date | B1: =B2 -> 45957
A2: dates | B2: ='VIX VOXX'!B23 -> 45957 | C2: ='VIX VOXX'!C23 -> 45954 | D2: ='VIX VOXX'!D23 -> 45953 | E2: ='VIX VOXX'!E23 -> 45952 | F2: ='VIX VOXX'!F23 -> 45951 | G2: ='VIX VOXX'!G23 -> 45950 | H2: ='VIX VOXX'!H23 -> 45947 | I2: ='VIX VOXX'!I23 -> 45946 | ... XFD2: ='VIX VOXX'!XFD23 -> 0
A3: =LEFT('VIX VOXX'!A24,4) -> FVS1 | B3: =RTD!O6 -> 17.925 | C3: ='VIX VOXX'!C24 -> 18.65 | D3: ='VIX VOXX'!D24 -> 18.85 | E3: ='VIX VOXX'!E24 -> 16.95 | F3: ='VIX VOXX'!F24 -> 16.9 | G3: ='VIX VOXX'!G24 -> 17.15 | H3: ='VIX VOXX'!H24 -> 20.55 | I3: ='VIX VOXX'!I24 -> 20.1 | J3: ='VIX VOXX'!J24 -> 19.45 | ... XFD3: ='VIX VOXX'!XFD24 -> 0
A4: =LEFT('VIX VOXX'!A25,4) -> FVS2 | B4: =RTD!O7 -> 17.975 | C4: ='VIX VOXX'!C25 -> 18.55 | D4: ='VIX VOXX'!D25 -> 18.95 | E4: ='VIX VOXX'!E25 -> 19 | F4: ='VIX VOXX'!F25 -> 18.7 | G4: ='VIX VOXX'!G25 -> 18.85 | H4: ='VIX VOXX'!H25 -> 21.5 | I4: ='VIX VOXX'!I25 -> 20.35 | J4: ='VIX VOXX'!J25 -> 19.95 | ... XFD4: ='VIX VOXX'!XFD25 -> 0
A5: =LEFT('VIX VOXX'!A26,4) -> FVS3 | B5: =RTD!O8 -> 19.625 | C5: ='VIX VOXX'!C26 -> 20.1 | D5: ='VIX VOXX'!D26 -> 20.6 | E5: ='VIX VOXX'!E26 -> 19.15 | F5: ='VIX VOXX'!F26 -> 18.9 | G5: ='VIX VOXX'!G26 -> 19.1 | H5: ='VIX VOXX'!H26 -> 20.95 | I5: ='VIX VOXX'!I26 -> 20.1 | J5: ='VIX VOXX'!J26 -> 19.85 | ... XFD5: ='VIX VOXX'!XFD26 -> 0
A6: =LEFT('VIX VOXX'!A27,4) -> FVS4 | B6: =RTD!O9 -> 19.875 | C6: ='VIX VOXX'!C27 -> 20.25 | D6: ='VIX VOXX'!D27 -> 20.6 | E6: ='VIX VOXX'!E27 -> 20.75 | F6: ='VIX VOXX'!F27 -> 20.5 | G6: ='VIX VOXX'!G27 -> 20.65 | H6: ='VIX VOXX'!H27 -> 21.85 | I6: ='VIX VOXX'!I27 -> 21.25 | J6: ='VIX VOXX'!J27 -> 21.1 | ... XFD6: ='VIX VOXX'!XFD27 -> 0
A7: =LEFT('VIX VOXX'!A28,4) -> FVS5 | B7: =RTD!O10 -> 20.075 | C7: ='VIX VOXX'!C28 -> 20.4 | D7: ='VIX VOXX'!D28 -> 20.65 | E7: ='VIX VOXX'!E28 -> 20.75 | F7: ='VIX VOXX'!F28 -> 20.5 | G7: ='VIX VOXX'!G28 -> 20.7 | H7: ='VIX VOXX'!H28 -> 21.5 | I7: ='VIX VOXX'!I28 -> 21.15 | J7: ='VIX VOXX'!J28 -> 21.1 | ... XFD7: ='VIX VOXX'!XFD28 -> 0
A8: =LEFT('VIX VOXX'!A29,4) -> FVS6 | B8: =RTD!O11 -> 20.175 | C8: ='VIX VOXX'!C29 -> 20.4 | D8: ='VIX VOXX'!D29 -> 20.6 | E8: ='VIX VOXX'!E29 -> 20.75 | F8: ='VIX VOXX'!F29 -> 20.55 | G8: ='VIX VOXX'!G29 -> 20.5 | H8: ='VIX VOXX'!H29 -> 21.4 | I8: ='VIX VOXX'!I29 -> 20.9 | J8: ='VIX VOXX'!J29 -> 20.8 | ... XFD8: ='VIX VOXX'!XFD29 -> 0
A9: =LEFT('VIX VOXX'!A30,4) -> FVS7 | B9: =RTD!O12 -> 20.175 | C9: ='VIX VOXX'!C30 -> 20.55 | D9: ='VIX VOXX'!D30 -> 20.6 | E9: ='VIX VOXX'!E30 -> 20.65 | F9: ='VIX VOXX'!F30 -> 20.45 | G9: ='VIX VOXX'!G30 -> 20.45 | H9: ='VIX VOXX'!H30 -> 21.15 | I9: ='VIX VOXX'!I30 -> 20.7 | J9: ='VIX VOXX'!J30 -> 20.55 | ... XFD9: ='VIX VOXX'!XFD30 -> 0

Sheet VIX VOXX
