Workbook

Sheet SZI0
A1: coulmnsss
A2: ='FF PX'!A2 -> Dates | B2: ='FF PX'!B2 -> 45946 | C2: ='FF PX'!C2 -> 45945 | D2: ='FF PX'!D2 -> 45944 | E2: ='FF PX'!E2 -> 45943 | F2: ='FF PX'!F2 -> 45940 | G2: ='FF PX'!G2 -> 45939 | H2: ='FF PX'!H2 -> 45938 | ... BSC2: ='FF PX'!BSC2 -> 43361
A3: SZI01 | B3: =RTD!B2 -> -8 | C3: =(-'FF PX'!C3+'SOFR1mo PX'!C3)*100 -> -7.5 | D3: =(-'FF PX'!D3+'SOFR1mo PX'!D3)*100 -> -6.5 | E3: =(-'FF PX'!E3+'SOFR1mo PX'!E3)*100 -> -6 | F3: =(-'FF PX'!F3+'SOFR1mo PX'!F3)*100 -> -5.75 | G3: =(-'FF PX'!G3+'SOFR1mo PX'!G3)*100 -> -5.5 | H3: =(-'FF PX'!H3+'SOFR1mo PX'!H3)*100 -> -6 | I3: =(-'FF PX'!I3+'SOFR1mo PX'!I3)*100 -> -6.5 | J3: =(-'FF PX'!J3+'SOFR1mo PX'!J3)*100 -> -6.5 | ... BSC3: =(-'FF PX'!BSC3+'SOFR1mo PX'!BSC3)*100 -> -3
A4: SZI02 | B4: =RTD!B3 -> -8 | C4: =(-'FF PX'!C4+'SOFR1mo PX'!C4)*100 -> -7.5 | D4: =(-'FF PX'!D4+'SOFR1mo PX'!D4)*100 -> -7 | E4: =(-'FF PX'!E4+'SOFR1mo PX'!E4)*100 -> -6.5 | F4: =(-'FF PX'!F4+'SOFR1mo PX'!F4)*100 -> -6.5 | G4: =(-'FF PX'!G4+'SOFR1mo PX'!G4)*100 -> -6 | H4: =(-'FF PX'!H4+'SOFR1mo PX'!H4)*100 -> -6.5 | I4: =(-'FF PX'!I4+'SOFR1mo PX'!I4)*100 -> -7 | J4: =(-'FF PX'!J4+'SOFR1mo PX'!J4)*100 -> -7 | ... BSC4: =(-'FF PX'!BSC4+'SOFR1mo PX'!BSC4)*100 -> -2
A5: SZI03 | B5: =RTD!B4 -> -9.5 | C5: =(-'FF PX'!C5+'SOFR1mo PX'!C5)*100 -> -9.5 | D5: =(-'FF PX'!D5+'SOFR1mo PX'!D5)*100 -> -8.5 | E5: =(-'FF PX'!E5+'SOFR1mo PX'!E5)*100 -> -9 | F5: =(-'FF PX'!F5+'SOFR1mo PX'!F5)*100 -> -8.5 | G5: =(-'FF PX'!G5+'SOFR1mo PX'!G5)*100 -> -8.5 | H5: =(-'FF PX'!H5+'SOFR1mo PX'!H5)*100 -> -8.5 | I5: =(-'FF PX'!I5+'SOFR1mo PX'!I5)*100 -> -9 | J5: =(-'FF PX'!J5+'SOFR1mo PX'!J5)*100 -> -9.5 | ... BSC5: =(-'FF PX'!BSC5+'SOFR1mo PX'!BSC5)*100 -> -3
A6: SZI04 | B6: =RTD!B5 -> -7 | C6: =(-'FF PX'!C6+'SOFR1mo PX'!C6)*100 -> -7 | D6: =(-'FF PX'!D6+'SOFR1mo PX'!D6)*100 -> -6.5 | E6: =(-'FF PX'!E6+'SOFR1mo PX'!E6)*100 -> -7 | F6: =(-'FF PX'!F6+'SOFR1mo PX'!F6)*100 -> -6.5 | G6: =(-'FF PX'!G6+'SOFR1mo PX'!G6)*100 -> -7 | H6: =(-'FF PX'!H6+'SOFR1mo PX'!H6)*100 -> -6.5 | I6: =(-'FF PX'!I6+'SOFR1mo PX'!I6)*100 -> -7 | J6: =(-'FF PX'!J6+'SOFR1mo PX'!J6)*100 -> -7.5 | ... BSC6: =(-'FF PX'!BSC6+'SOFR1mo PX'!BSC6)*100 -> -3
A7: SZI05 | B7: =RTD!B6 -> -6 | C7: =(-'FF PX'!C7+'SOFR1mo PX'!C7)*100 -> -6 | D7: =(-'FF PX'!D7+'SOFR1mo PX'!D7)*100 -> -5.5 | E7: =(-'FF PX'!E7+'SOFR1mo PX'!E7)*100 -> -6 | F7: =(-'FF PX'!F7+'SOFR1mo PX'!F7)*100 -> -5.5 | G7: =(-'FF PX'!G7+'SOFR1mo PX'!G7)*100 -> -6 | H7: =(-'FF PX'!H7+'SOFR1mo PX'!H7)*100 -> -5.5 | I7: =(-'FF PX'!I7+'SOFR1mo PX'!I7)*100 -> -6 | J7: =(-'FF PX'!J7+'SOFR1mo PX'!J7)*100 -> -6.5 | ... BSC7: =(-'FF PX'!BSC7+'SOFR1mo PX'!BSC7)*100 -> -2
A8: SZI06 | B8: =RTD!B7 -> -6.5 | C8: =(-'FF PX'!C8+'SOFR1mo PX'!C8)*100 -> -6.5 | D8: =(-'FF PX'!D8+'SOFR1mo PX'!D8)*100 -> -6 | E8: =(-'FF PX'!E8+'SOFR1mo PX'!E8)*100 -> -6.5 | F8: =(-'FF PX'!F8+'SOFR1mo PX'!F8)*100 -> -6.5 | G8: =(-'FF PX'!G8+'SOFR1mo PX'!G8)*100 -> -6.5 | H8: =(-'FF PX'!H8+'SOFR1mo PX'!H8)*100 -> -6.5 | I8: =(-'FF PX'!I8+'SOFR1mo PX'!I8)*100 -> -6.5 | J8: =(-'FF PX'!J8+'SOFR1mo PX'!J8)*100 -> -7 | ... BSC8: =(-'FF PX'!BSC8+'SOFR1mo PX'!BSC8)*100 -> -2.5
A9: SZI07 | B9: =RTD!B8 -> -6 | C9: =(-'FF PX'!C9+'SOFR1mo PX'!C9)*100 -> -4 | D9: =(-'FF PX'!D9+'SOFR1mo PX'!D9)*100 -> 3.5 | E9: =(-'FF PX'!E9+'SOFR1mo PX'!E9)*100 -> 2.5 | F9: =(-'FF PX'!F9+'SOFR1mo PX'!F9)*100 -> -1 | G9: =(-'FF PX'!G9+'SOFR1mo PX'!G9)*100 -> -8 | H9: =(-'FF PX'!H9+'SOFR1mo PX'!H9)*100 -> -9.5 | I9: =(-'FF PX'!I9+'SOFR1mo PX'!I9)*100 -> -10.5 | J9: =(-'FF PX'!J9+'SOFR1mo PX'!J9)*100 -> -10.5 | ... BSC9: =(-'FF PX'!BSC9+'SOFR1mo PX'!BSC9)*100 -> -3
A10: SZI08 | B10: =RTD!B9 -> -5.5 | C10: =(-'FF PX'!C10+'SOFR1mo PX'!C10)*100 -> -5 | D10: =(-'FF PX'!D10+'SOFR1mo PX'!D10)*100 -> -5 | E10: =(-'FF PX'!E10+'SOFR1mo PX'!E10)*100 -> -5.5 | F10: =(-'FF PX'!F10+'SOFR1mo PX'!F10)*100 -> -5.5 | G10: =(-'FF PX'!G10+'SOFR1mo PX'!G10)*100 -> -5.5 | H10: =(-'FF PX'!H10+'SOFR1mo PX'!H10)*100 -> -5.5 | I10: =(-'FF PX'!I10+'SOFR1mo PX'!I10)*100 -> -5.5 | J10: =(-'FF PX'!J10+'SOFR1mo PX'!J10)*100 -> -6 | ... BSC10: =(-'FF PX'!BSC10+'SOFR1mo PX'!BSC10)*100 -> 19
A11: SZI09 | B11: =RTD!B10 -> -6 | C11: =(-'FF PX'!C11+'SOFR1mo PX'!C11)*100 -> -5.5 | D11: =(-'FF PX'!D11+'SOFR1mo PX'!D11)*100 -> -6 | E11: =(-'FF PX'!E11+'SOFR1mo PX'!E11)*100 -> -6 | F11: =(-'FF PX'!F11+'SOFR1mo PX'!F11)*100 -> -6 | G11: =(-'FF PX'!G11+'SOFR1mo PX'!G11)*100 -> -6 | H11: =(-'FF PX'!H11+'SOFR1mo PX'!H11)*100 -> -6 | I11: =(-'FF PX'!I11+'SOFR1mo PX'!I11)*100 -> -6.5 | J11: =(-'FF PX'!J11+'SOFR1mo PX'!J11)*100 -> -6.5 | ... BSC11: =(-'FF PX'!BSC11+'SOFR1mo PX'!BSC11)*100 -> #VALUE!
A12: SZI10 | B12: =RTD!B11 -> -5.25 | C12: =(-'FF PX'!C12+'SOFR1mo PX'!C12)*100 -> -5 | D12: =(-'FF PX'!D12+'SOFR1mo PX'!D12)*100 -> -5.5 | E12: =(-'FF PX'!E12+'SOFR1mo PX'!E12)*100 -> -5.5 | F12: =(-'FF PX'!F12+'SOFR1mo PX'!F12)*100 -> -5.5 | G12: =(-'FF PX'!G12+'SOFR1mo PX'!G12)*100 -> -5 | H12: =(-'FF PX'!H12+'SOFR1mo PX'!H12)*100 -> -5.5 | I12: =(-'FF PX'!I12+'SOFR1mo PX'!I12)*100 -> -6 | J12: =(-'FF PX'!J12+'SOFR1mo PX'!J12)*100 -> -6 | ... BSC12: =(-'FF PX'!BSC12+'SOFR1mo PX'!BSC12)*100 -> #VALUE!
A13: SZI11 | B13: =RTD!B12 -> -5 | C13: =(-'FF PX'!C13+'SOFR1mo PX'!C13)*100 -> -5 | D13: =(-'FF PX'!D13+'SOFR1mo PX'!D13)*100 -> -5.5 | E13: =(-'FF PX'!E13+'SOFR1mo PX'!E13)*100 -> -5.5 | F13: =(-'FF PX'!F13+'SOFR1mo PX'!F13)*100 -> -5.5 | G13: =(-'FF PX'!G13+'SOFR1mo PX'!G13)*100 -> -5 | H13: =(-'FF PX'!H13+'SOFR1mo PX'!H13)*100 -> -5.5 | I13: =(-'FF PX'!I13+'SOFR1mo PX'!I13)*100 -> -6 | J13: =(-'FF PX'!J13+'SOFR1mo PX'!J13)*100 -> -6 | ... BSC13: =(-'FF PX'!BSC13+'SOFR1mo PX'!BSC13)*100 -> #VALUE!
A14: SZI12 | B14: =RTD!B13 -> -5.75 | C14: =(-'FF PX'!C14+'SOFR1mo PX'!C14)*100 -> -4 | D14: =(-'FF PX'!D14+'SOFR1mo PX'!D14)*100 -> 7 | E14: =(-'FF PX'!E14+'SOFR1mo PX'!E14)*100 -> 5.5 | F14: =(-'FF PX'!F14+'SOFR1mo PX'!F14)*100 -> 0.5 | G14: =(-'FF PX'!G14+'SOFR1mo PX'!G14)*100 -> -7 | H14: =(-'FF PX'!H14+'SOFR1mo PX'!H14)*100 -> -9.5 | I14: =(-'FF PX'!I14+'SOFR1mo PX'!I14)*100 -> -10.5 | J14: =(-'FF PX'!J14+'SOFR1mo PX'!J14)*100 -> -11 | ... BSC14: =(-'FF PX'!BSC14+'SOFR1mo PX'!BSC14)*100 -> #VALUE!
A15: SZI13 | B15: =RTD!B14 -> -5.25 | C15: =(-'FF PX'!C15+'SOFR1mo PX'!C15)*100 -> -5 | D15: =(-'FF PX'!D15+'SOFR1mo PX'!D15)*100 -> -5.5 | E15: =(-'FF PX'!E15+'SOFR1mo PX'!E15)*100 -> -5.5 | F15: =(-'FF PX'!F15+'SOFR1mo PX'!F15)*100 -> -5.5 | G15: =(-'FF PX'!G15+'SOFR1mo PX'!G15)*100 -> -5 | H15: =(-'FF PX'!H15+'SOFR1mo PX'!H15)*100 -> -5.5 | I15: =(-'FF PX'!I15+'SOFR1mo PX'!I15)*100 -> -6 | J15: =(-'FF PX'!J15+'SOFR1mo PX'!J15)*100 -> -5.5 | ... BSC15: =(-'FF PX'!BSC15+'SOFR1mo PX'!BSC15)*100 -> #VALUE!

Sheet FF PX
