Workbook

Sheet VIX
B1: latest date in settleemt | E1: ='VIX VOXX'!B3 -> 45930
A2: ='VIX VOXX'!A3 -> Dates | B2: ='VIX VOXX'!B3 -> 45930 | C2: ='VIX VOXX'!C3 -> 45929 | D2: ='VIX VOXX'!D3 -> 45926 | E2: ='VIX VOXX'!E3 -> 45925 | F2: ='VIX VOXX'!F3 -> 45924 | G2: ='VIX VOXX'!G3 -> 45923 | H2: ='VIX VOXX'!H3 -> 45922 | ... FRD2: ='VIX VOXX'!FRD3 -> 0
A3: VIX1 | B3: =IF([1]VIX!C46="",C3,[1]VIX!C46) -> 18.000 | C3: ='VIX VOXX'!C4 -> 17.7466 | D3: ='VIX VOXX'!D4 -> 17.4931 | E3: ='VIX VOXX'!E4 -> 18.3333 | F3: ='VIX VOXX'!F4 -> 18.0413 | G3: ='VIX VOXX'!G4 -> 18.34 | H3: ='VIX VOXX'!H4 -> 18.0476 | I3: ='VIX VOXX'!I4 -> 17.7179 | J3: ='VIX VOXX'!J4 -> 17.677 | ... FRD3: ='VIX VOXX'!FRD4 -> 0
A4: VIX2 | B4: =IF([1]VIX!C47="",C4,[1]VIX!C47) -> 19.450 | C4: ='VIX VOXX'!C5 -> 19.2967 | D4: ='VIX VOXX'!D5 -> 19.0568 | E4: ='VIX VOXX'!E5 -> 19.7125 | F4: ='VIX VOXX'!F5 -> 19.5247 | G4: ='VIX VOXX'!G5 -> 19.708 | H4: ='VIX VOXX'!H5 -> 19.534 | I4: ='VIX VOXX'!I5 -> 19.2825 | J4: ='VIX VOXX'!J5 -> 19.25 | ... FRD4: ='VIX VOXX'!FRD5 -> 0
A5: VIX3 | B5: =IF([1]VIX!C48="",C5,[1]VIX!C48) -> 19.950 | C5: ='VIX VOXX'!C6 -> 19.8489 | D5: ='VIX VOXX'!D6 -> 19.6556 | E5: ='VIX VOXX'!E6 -> 20.197 | F5: ='VIX VOXX'!F6 -> 20.0542 | G5: ='VIX VOXX'!G6 -> 20.225 | H5: ='VIX VOXX'!H6 -> 20.0659 | I5: ='VIX VOXX'!I6 -> 19.8995 | J5: ='VIX VOXX'!J6 -> 19.875 | ... FRD5: ='VIX VOXX'!FRD6 -> 0
A6: VIX4 | B6: =IF([1]VIX!C49="",C6,[1]VIX!C49) -> 20.850 | C6: ='VIX VOXX'!C7 -> 20.7076 | D6: ='VIX VOXX'!D7 -> 20.6004 | E6: ='VIX VOXX'!E7 -> 21.089 | F6: ='VIX VOXX'!F7 -> 20.9883 | G6: ='VIX VOXX'!G7 -> 21.125 | H6: ='VIX VOXX'!H7 -> 21.025 | I6: ='VIX VOXX'!I7 -> 20.85 | J6: ='VIX VOXX'!J7 -> 20.875 | ... FRD6: ='VIX VOXX'!FRD7 -> 0
A7: VIX5 | B7: =IF([1]VIX!C50="",C7,[1]VIX!C50) -> 21.300 | C7: ='VIX VOXX'!C8 -> 21.1997 | D7: ='VIX VOXX'!D8 -> 21.075 | E7: ='VIX VOXX'!E8 -> 21.5002 | F7: ='VIX VOXX'!F8 -> 21.4475 | G7: ='VIX VOXX'!G8 -> 21.5818 | H7: ='VIX VOXX'!H8 -> 21.4449 | I7: ='VIX VOXX'!I8 -> 21.2535 | J7: ='VIX VOXX'!J8 -> 21.275 | ... FRD7: ='VIX VOXX'!FRD8 -> 0
A8: VIX6 | B8: =IF([1]VIX!C51="",C8,[1]VIX!C51) -> 21.400 | C8: ='VIX VOXX'!C9 -> 21.275 | D8: ='VIX VOXX'!D9 -> 21.204 | E8: ='VIX VOXX'!E9 -> 21.622 | F8: ='VIX VOXX'!F9 -> 21.55 | G8: ='VIX VOXX'!G9 -> 21.625 | H8: ='VIX VOXX'!H9 -> 21.525 | I8: ='VIX VOXX'!I9 -> 21.35 | J8: ='VIX VOXX'!J9 -> 21.375 | ... FRD8: ='VIX VOXX'!FRD9 -> 0
A9: VIX7 | B9: =IF([1]VIX!C52="",C9,[1]VIX!C52) -> 21.550 | C9: ='VIX VOXX'!C10 -> 21.4605 | D9: ='VIX VOXX'!D10 -> 21.3805 | E9: ='VIX VOXX'!E10 -> 21.7258 | F9: ='VIX VOXX'!F10 -> 21.65 | G9: ='VIX VOXX'!G10 -> 21.725 | H9: ='VIX VOXX'!H10 -> 21.625 | I9: ='VIX VOXX'!I10 -> 21.5 | J9: ='VIX VOXX'!J10 -> 21.5104 | ... FRD9: ='VIX VOXX'!FRD10 -> 0
A10: VIX8 | B10: =IF([1]VIX!C53="",C10,[1]VIX!C53) -> 21.4878 | C10: ='VIX VOXX'!C11 -> 21.4878 | D10: ='VIX VOXX'!D11 -> 21.4251 | E10: ='VIX VOXX'!E11 -> 21.75 | F10: ='VIX VOXX'!F11 -> 21.675 | G10: ='VIX VOXX'!G11 -> 21.725 | H10: ='VIX VOXX'!H11 -> 21.623 | I10: ='VIX VOXX'!I11 -> 21.5 | J10: ='VIX VOXX'!J11 -> 21.5396 | ... FRD10: ='VIX VOXX'!FRD11 -> 0
A11: VIX9 | B11: =IF([1]VIX!C54="",C11,[1]VIX!C54) -> 21.575 | C11: ='VIX VOXX'!C12 -> 21.575 | D11: ='VIX VOXX'!D12 -> 21.55 | E11: ='VIX VOXX'!E12 -> 21.775 | F11: ='VIX VOXX'!F12 -> 21.825 | G11: ='VIX VOXX'!G12 -> 21.875 | H11: ='VIX VOXX'!H12 -> 21.623 | I11: ='VIX VOXX'!I12 -> 21.55 | J11: ='VIX VOXX'!J12 -> 21.55 | ... FRD11: ='VIX VOXX'!FRD12 -> 0

Sheet VIX VOXX
