Workbook

Sheet VX- VOX
A1: latest date | B1: =B2 -> 45957
A2: =settle!A3 -> Dates | B2: =settle!B3 -> 45957 | C2: =settle!C3 -> 45954 | D2: =settle!D3 -> 45953 | E2: =settle!E3 -> 45952 | F2: =settle!F3 -> 45951 | G2: =settle!G3 -> 45950 | H2: =settle!H3 -> 45947 | ... FRD2: =settle!FRD3 -> 0
A3: VX- VOX1 | B3: =RTD!R19 -> 0.75 | C3: =(settle!B4-settle!B5)-(settle!B24- settle!B25) -> -0.8058 | D3: =(settle!C4-settle!C5)-(settle!C24- settle!C25) -> -0.8058 | E3: =(settle!D4-settle!D5)-(settle!D24- settle!D25) -> -0.6015 | F3: =(settle!E4-settle!E5)-(settle!E24- settle!E25) -> 1.4461 | G3: =(settle!F4-settle!F5)-(settle!F24- settle!F25) -> 0.7744 | H3: =(settle!G4-settle!G5)-(settle!G24- settle!G25) -> 0.9682 | I3: =(settle!H4-settle!H5)-(settle!H24- settle!H25) -> 1.1541 | J3: =(settle!I4-settle!I5)-(settle!I24- settle!I25) -> 1.8617 | ... FRD3: =(settle!FRC4-settle!FRC5)-(settle!FRC24- settle!FRC25) -> 0
A4: VX- VOX2 | B4: =RTD!R20 -> -0.425 | C4: =(settle!B5-settle!B6)-(settle!B25- settle!B26) -> 0.404 | D4: =(settle!C5-settle!C6)-(settle!C25- settle!C26) -> 0.404 | E4: =(settle!D5-settle!D6)-(settle!D25- settle!D26) -> 0.5194 | F4: =(settle!E5-settle!E6)-(settle!E25- settle!E26) -> -0.4087 | G4: =(settle!F5-settle!F6)-(settle!F25- settle!F26) -> -0.5487 | H4: =(settle!G5-settle!G6)-(settle!G25- settle!G26) -> -0.3652 | I4: =(settle!H5-settle!H6)-(settle!H25- settle!H26) -> -0.6902 | J4: =(settle!I5-settle!I6)-(settle!I25- settle!I26) -> 0.157 | ... FRD4: =(settle!FRC5-settle!FRC6)-(settle!FRC25- settle!FRC26) -> 0
A5: VX- VOX3 | B5: =RTD!R21 -> 0.425 | C5: =(settle!B6-settle!B7)-(settle!B26- settle!B27) -> -0.4051 | D5: =(settle!C6-settle!C7)-(settle!C26- settle!C27) -> -0.4051 | E5: =(settle!D6-settle!D7)-(settle!D26- settle!D27) -> -0.5004 | F5: =(settle!E6-settle!E7)-(settle!E26- settle!E27) -> 0.5129 | G5: =(settle!F6-settle!F7)-(settle!F26- settle!F27) -> 0.4525 | H5: =(settle!G6-settle!G7)-(settle!G26- settle!G27) -> 0.5825 | I5: =(settle!H6-settle!H7)-(settle!H26- settle!H27) -> 0.1973 | J5: =(settle!I6-settle!I7)-(settle!I26- settle!I27) -> 0.7114 | ... FRD5: =(settle!FRC6-settle!FRC7)-(settle!FRC26- settle!FRC27) -> 0
A6: VX- VOX4 | B6: =RTD!R22 -> 0.15 | C6: =(settle!B7-settle!B8)-(settle!B27- settle!B28) -> -0.1319 | D6: =(settle!C7-settle!C8)-(settle!C27- settle!C28) -> -0.1319 | E6: =(settle!D7-settle!D8)-(settle!D27- settle!D28) -> -0.2089 | F6: =(settle!E7-settle!E8)-(settle!E27- settle!E28) -> -0.4951 | G6: =(settle!F7-settle!F8)-(settle!F27- settle!F28) -> -0.4619 | H6: =(settle!G7-settle!G8)-(settle!G27- settle!G28) -> -0.3447 | I6: =(settle!H7-settle!H8)-(settle!H27- settle!H28) -> -0.554 | J6: =(settle!I7-settle!I8)-(settle!I27- settle!I28) -> -0.1522 | ... FRD6: =(settle!FRC7-settle!FRC8)-(settle!FRC27- settle!FRC28) -> 0
A7: VX- VOX5 | B7: =RTD!R23 -> 0.2 | C7: =(settle!B8-settle!B9)-(settle!B28- settle!B29) -> -0.2489 | D7: =(settle!C8-settle!C9)-(settle!C28- settle!C29) -> -0.2489 | E7: =(settle!D8-settle!D9)-(settle!D28- settle!D29) -> -0.3029 | F7: =(settle!E8-settle!E9)-(settle!E28- settle!E29) -> -0.2029 | G7: =(settle!F8-settle!F9)-(settle!F28- settle!F29) -> -0.1683 | H7: =(settle!G8-settle!G9)-(settle!G28- settle!G29) -> -0.4231 | I7: =(settle!H8-settle!H9)-(settle!H28- settle!H29) -> -0.1461 | J7: =(settle!I8-settle!I9)-(settle!I28- settle!I29) -> -0.1558 | ... FRD7: =(settle!FRC8-settle!FRC9)-(settle!FRC28- settle!FRC29) -> 0
A8: VX- VOX6 | B8: =RTD!R24 -> 0.1 | C8: =(settle!B9-settle!B10)-(settle!B29- settle!B30) -> 0.0247 | D8: =(settle!C9-settle!C10)-(settle!C29- settle!C30) -> 0.0247 | E8: =(settle!D9-settle!D10)-(settle!D29- settle!D30) -> -0.0604 | F8: =(settle!E9-settle!E10)-(settle!E29- settle!E30) -> -0.3023 | G8: =(settle!F9-settle!F10)-(settle!F29- settle!F30) -> -0.28 | H8: =(settle!G9-settle!G10)-(settle!G29- settle!G30) -> -0.294 | I8: =(settle!H9-settle!H10)-(settle!H29- settle!H30) -> -0.3474 | J8: =(settle!I9-settle!I10)-(settle!I29- settle!I30) -> -0.2348 | ... FRD8: =(settle!FRC9-settle!FRC10)-(settle!FRC29- settle!FRC30) -> 0

Sheet settle
